Workbook
Name BBDD: '[1]Centro Nacional'!$AB$4:$AW$90
Name tabla_baj_hdp: '[2]TABLA HANDICAPS'!$E$4:$V$9

Sheet Jugadores
A1: Orden | B1: Nombre | C1: Licencia | D1: Mote | E1: Icono | F1: Movil | G1: Email | H1: Nombre y Apellidos | I1: 2019-2020 | J1: 2021 | K1: 2022 | L1: 2023 | M1: 2024 | N1: 2025 | O1: 2026
A2: 1 | B2: Nacho Gonzalez | C2: CME6076737 | D2: Nacho | E2: 🖐🏻 | H2: Ignacio González Salvador | I2: Si | J2: Si | K2: Si | L2: Si | M2: Si | N2: Si | O2: Si | W2: 🕺 | AF2: rneo Encin, 1 liga Cuartilla 28/12 10:50h-11:20h
A3: 2 | B3: Ignacio Cadarso | C3: CME6501940 | D3: Ignacio | E3: 😺 | H3: Ignacio Cadarso Amador | I3: Si | J3: Si | K3: Si | L3: Si | M3: Si | N3: Si | O3: Si | AF3: 1. David 🐗
A4: 3 | B4: Alfonso Hidalgo | C4: CME6255829 | D4: Alfonso | E4: 🏌️‍♂️ | F4: +34 669 459 016 | G4: hidalgoalfonso66@gmail.com | H4: Alfonso Hidalgo Lopez de Ayala | I4: Si | J4: Si | K4: Si | L4: Si | M4: Si | N4: Si | O4: Si | AF4: 2. Gifu 🤓
A5: 4 | B5: Francisco Alvarez | C5: CME6389026 | D5: Paco | E5: 🎸 | G5: falvarezoliva@gmail.com | H5: Francisco Alvarez Oliva | I5: Si | J5: Si | K5: Si | L5: Si | M5: Si | N5: Si | O5: Si | AF5: 3. Alvaro 🏊🏼‍♂️
A6: 5 | B6: Alvaro Aguirre | C6: CME6628917 | D6: Gifu | E6: 🤓 | F6: 666450522 | G6: aaguirrerodriguez@gmail.com | H6: Alvaro Aguirre Rodriguez | I6: Si | J6: Si | K6: Si | L6: Si | M6: Si | N6: Si | O6: Si | AF6: 4. Nacho 🖐️
A7: 6 | B7: José Pablo Guil | C7: CME6089043 | D7: JP | E7: ✈️ | H7: José Pablo Guil Salvador | I7: Si | J7: Si | K7: Si | L7: Si | M7: Si | N7: Si | O7: Si | AF7: 5. Alfonso 🏌️‍♂️
A8: 7 | B8: Javier Gonzalez Salvador | C8: CME6296170 | D8: Javi | E8: 🪱 | H8: Francisco Javier Gonzalez Salvador | I8: Si | J8: Si | K8: Si | L8: Si | M8: Si | N8: Si | O8: Si | U8: 🪱 | V8: 🐍 | AE8: 🐲 | AF8: 6. Miche 🐲
A9: 8 | B9: J. Enrique Gonzalez | C9: CME6392431 | D9: Kike | E9: 💀 | H9: Julio Enrique Gonzalez Salvador | I9: Si | J9: Si | K9: Si | L9: Si | M9: Si | N9: Si | O9: Si
A10: 9 | B10: Alvaro Nieto | C10: CM02386035 | D10: Alvaro | E10: 🏊 | H10: Alvaro Nieto Esteban | I10: Si | J10: Si | K10: Si | L10: Si | M10: Si | N10: Si | O10: Si
A11: 10 | B11: Pablo Munitiz | C11: CME6756891 | D11: Muni | E11: 👮‍♂️ | H11: Pablo Munitiz San Martin | I11: Si | J11: Si | K11: No | L11: No | M11: No | N11: No | O11: No
A12: 11 | B12: David Sequera | C12: CME6308858 | D12: David | E12: 🐗 | F12: +34 620 829 471 | G12: davidsequera@icloud.com | H12: David Sequera Merino | I12: Si | J12: Si | K12: Si | L12: Si | M12: Si | N12: Si | O12: Si
A13: 12 | B13: Angel Hernandez | C13: CME6169895 | D13: Angel | E13: 🏆 | H13: Angel Hernandez Rilova | I13: Si | J13: No | K13: Si | L13: Si | M13: Si | N13: Si | O13: Si | T13: BP16300744 | U13: 🤠 | V13: 🍄 | W13: 🍴 | X13: 🐣 | Y13: 🏆
A14: 13 | B14: GLEZ JUAN JOSÉ | C14: CME6296171 | D14: Juanjo | E14: 🦍 | H14: Juan José Gonzalez Salvador | I14: Si | J14: Si | K14: Si | L14: Si | M14: Si | N14: Si | O14: Si
A15: 14 | B15: Jesus Touceda | C15: CME6296994 | D15: Jesús | E15: 🍄 | H15: Jesus Rodriguez Touceda | I15: Si | J15: Si | K15: Si | L15: Si | M15: Si | N15: Si | O15: Si
A16: 15 | B16: Luis Escudero | C16: CME6760523 | D16: Lucho | E16: 🏍 | H16: Luis Manuel Escudero Mas | I16: Si | J16: No | K16: No | L16: No | M16: No | N16: No | O16: No
A17: 16 | B17: Javier Cervera | C17: CME6259082 | D17: Virus | E17: 🦠 | F17: 633 768 075 | G17: despacho@cerveraprocurador.com | H17: Javier Cervera Rodriguez | I17: Si | J17: Si | K17: Si | L17: Si | M17: Si | N17: Si | O17: Si
A18: 17 | B18: Francisco Hidalgo | C18: CME6632866 | D18: Fran | E18: ⚓️ | H18: Francisco Hidalgo Lopez de Ayala | I18: Si | J18: Si | K18: Si | L18: Si | M18: Si | N18: Si | O18: Si
A19: 18 | B19: Miguel Diaz Del Moral | C19: AM07096812 | D19: Cañita | E19: 🍺 | H19: Miguel Diaz del Moral Berdun | I19: No | J19: No | K19: No | L19: No | M19: No | N19: No | O19: No | V19: ☠️ | W19: 🦠
A20: 19 | B20: Miche Lopez | C20: CMA8937096 | D20: Miche | E20: 🐲 | H20: Vicente Lopez Calderón | I20: No | J20: Si | K20: Si | L20: Si | M20: Si | N20: Si | O20: Si
A21: 20 | B21: Alvaro Montoya | C21: AM62044928 | D21: Monti | E21: ⛳ | F21: 670 847 722 | G21: alvaro@bestmedia.es | H21: Alvaro Montoya Soler | I21: No | J21: Inv | K21: Si | L21: Si | M21: Si | N21: Si | O21: Si | T21: ⛳ | U21: 🏃‍♂️
A22: 21 | B22: Ruslan Kochman | C22: CM15639290 | D22: Rus | E22: 🧸 | H22: Ruslan Kochman | I22: No | J22: Inv | K22: Si | L22: Si | M22: Si | N22: Si | O22: Si
A23: 22 | B23: Nacho Casas | C23: CM15620350 | D23: Nachete | E23: 🐅 | F23: 619 893 390 | G23: ncasmartin0@gmail.com | H23: Ignacio Casas Martín | I23: No | J23: Inv | K23: Si | L23: Si | M23: Si | N23: Si | O23: Si | U23: 🐅
A24: 23 | B24: Franck Benouniche | C24: CM15259757 | D24: Franck | E24: 🏹 | H24: Franck Benouniche Founier | I24: No | J24: Inv | K24: Si | L24: Si | M24: Si | N24: Si | O24: Si
A25: 24 | B25: Javier Lopez Gullón | C25: CME6765008 | D25: Cuñao | E25: 👨🏻‍⚖️ | H25: Francisco Javier Lopez Gullón | I25: No | J25: No | K25: Si | L25: Si | M25: Si | N25: Si | O25: Si
A26: 25 | B26: Javier Chiralt | C26: CM52419365 | D26: Chiralt | E26: 🍗 | H26: Javier Chiralt Perez | I26: No | J26: No | K26: Si | L26: Si | M26: Si | N26: Si | O26: Si
A27: 26 | B27: Alfonso Zorrilla | C27: CM00159560 | D27: A Zorrilla | E27: 🐺 | H27: Alfonso Zorrilla | I27: No | J27: Inv | K27: Inv | L27: Inv | M27: Inv | N27: Inv | O27: Inv
A28: 27 | B28: Enrique Gonzalez R | C28: CM87625434 | D28: Enrique | E28: 🚵‍♂ | H28: Pablo Enrique Gonzalez Ramirez | I28: No | J28: No | K28: Si | L28: Si | M28: Si | N28: Si | O28: Si
A29: 28 | B29: Alejandro Arcos | C29: CM00358747 | D29: Alex | E29: 🦐 | H29: Alejandro Arcos Campillo | I29: No | J29: No | K29: Inv | L29: Si | M29: Si | N29: Si | O29: Si
A30: 29 | B30: Antonio Carmona | C30: CM00157281 | D30: Antonio | H30: Antonio Carmona Quesada | I30: No | J30: No | K30: Inv | L30: Si | M30: Si | N30: Si | O30: Si
A31: 30 | B31: Santi Diaz | C31: CM05807868 | D31: Santi | H31: Santiago Diaz Dominguez | I31: No | J31: No | K31: Inv | L31: Inv | M31: Inv | N31: Si | O31: Si
A32: 31 | B32: Juan Jose Aguado | C32: CM15989410 | D32: Juancho | E32: 🦎 | H32: Juan Jose Aguado Rodriguez de Trio | I32: No | J32: No | K32: Inv | L32: Si | M32: Si | N32: Si | O32: Si
A33: 32 | B33: Jaime Villanueva | C33: CMA8990856 | D33: Villanueva | H33: Jaime Villanueva Ghisleri | I33: No | J33: No | K33: Inv | L33: Inv | M33: Inv | N33: Inv | O33: Si
A34: 33 | B34: Carlos Hijas | C34: CM81957137 | D34: Hijas | H34: Carlos Hijas Galvez | I34: No | J34: No | K34: Inv | L34: No | M34: No | N34: No | O34: No
A35: 34 | B35: Carlos Maestro | C35: 4401188458 | D35: Carlitos | E35: 🔥 | H35: Carlos Maestro Aguilera | I35: No | J35: No | K35: Inv | L35: Si | M35: Si | N35: Si | O35: Si | T35: 🥟
A36: 35 | B36: Jorge Alberto Martínez Sánchez | C36: AM12098542 | D36: Jorge | H36: Jorge Alberto Martínez Sánchez | I36: No | J36: No | K36: Inv | L36: Si | M36: Si | N36: Si | O36: Si
A37: 36 | B37: Ignacio Gracia Charlez | C37: CM15762628 | D37: I Gracia | H37: Ignacio Gracia Charlez | I37: No | J37: No | K37: Inv | L37: Inv | M37: Inv | N37: Inv | O37: Inv
A38: 37 | B38: Eduardo Buendía | C38: CM00192650 | D38: Eduardo | E38: 🐧 | F38: +34 682 396 740 | G38: Buendiamdp@hotmail.com | H38: Eduardo Buendía Pan | I38: No | J38: No | K38: Inv | L38: Si | M38: Si | N38: Si | O38: Si | T38: 🐧 | U38: 🏉 | W38: duardo | X38: 🐧
A39: 38 | B39: Javier Arcos | C39: CM00065999 | D39: J.Arcos | E39: 🌵 | H39: Javier Arcos Campillo | I39: No | J39: No | K39: Inv | L39: Si | M39: Si | N39: Si | O39: Si
A40: 39 | B40: Emiliano Buendía | C40: 1017680906 | D40: Emi | H40: Emiliano Buendía Stati | I40: No | J40: No | K40: Inv | L40: Inv | M40: Inv | N40: Inv | O40: Inv
...

Sheet Calendario
A1: Fecha | B1: Temporada | C1: NºTorneo | D1: Campo | E1: Barras | F1: TorneoID | G1: Organizado | H1: RdosQuitar | I1: NºTornPunt | J1: Campo-Barras | K1: Tee Salida | L1: Salidas | M1: DiaSem | N1: Precio | O1: Salida | P1: Hora | Q1: Observaciones | R1: Competicion | S1: Temp-Ntorn | U1: % Puntúan
A2: 45346 | B2: 2024 | C2: 1 | D2: Retamares | E2: Amarillas | F2: 2 | G2: David | H2: 0 | I2: =+dCalendario[[#This Row],[NºTorneo]]-dCalendario[[#This Row],[RdosQuitar]] -> 1 | J2: =+dCalendario[[#This Row],[Campo]]&"-"&dCalendario[[#This Row],[Barras]] -> Retamares-Amarillas | K2: 1 | L2: Hdcp | M2: =+WEEKDAY(dCalendario[[#This Row],[Fecha]],2) -> 6 | N2: 60 | O2: Progresivas | P2: 12:00 | Q2: Reserva 32 salidas | R2: Liga | S2: =+dCalendario[[#This Row],[Temporada]]&":"&dCalendario[[#This Row],[NºTorneo]] -> 2024:1 | U2: =+dCalendario[[#This Row],[NºTornPunt]]/dCalendario[[#This Row],[NºTorneo]] -> 1
A3: 45360 | B3: 2024 | C3: 2 | D3: El Encin | E3: Amarillas | F3: 2 | G3: David | H3: 1 | I3: =+dCalendario[[#This Row],[NºTorneo]]-dCalendario[[#This Row],[RdosQuitar]] -> 1 | J3: =+dCalendario[[#This Row],[Campo]]&"-"&dCalendario[[#This Row],[Barras]] -> El Encin-Amarillas | L3: Hdcp | M3: =+WEEKDAY(dCalendario[[#This Row],[Fecha]],2) -> 6 | R3: Liga | S3: =+dCalendario[[#This Row],[Temporada]]&":"&dCalendario[[#This Row],[NºTorneo]] -> 2024:2 | U3: =+dCalendario[[#This Row],[NºTornPunt]]/dCalendario[[#This Row],[NºTorneo]] -> 0.5
A4: 45409 | B4: 2024 | C4: 3 | D4: Cabanillas | E4: Amarillas | F4: 2 | G4: David | H4: 1 | I4: =+dCalendario[[#This Row],[NºTorneo]]-dCalendario[[#This Row],[RdosQuitar]] -> 2 | J4: =+dCalendario[[#This Row],[Campo]]&"-"&dCalendario[[#This Row],[Barras]] -> Cabanillas-Amarillas | L4: Clasif | M4: =+WEEKDAY(dCalendario[[#This Row],[Fecha]],2) -> 6 | R4: Liga | S4: =+dCalendario[[#This Row],[Temporada]]&":"&dCalendario[[#This Row],[NºTorneo]] -> 2024:3 | U4: =+dCalendario[[#This Row],[NºTornPunt]]/dCalendario[[#This Row],[NºTorneo]] -> 0.66666667
A5: 45430 | B5: 2024 | C5: 4 | D5: Saldaña | E5: Amarillas | F5: 3 | G5: David | H5: 1 | I5: =+dCalendario[[#This Row],[NºTorneo]]-dCalendario[[#This Row],[RdosQuitar]] -> 3 | J5: =+dCalendario[[#This Row],[Campo]]&"-"&dCalendario[[#This Row],[Barras]] -> Saldaña-Amarillas | L5: Hdcp | M5: =+WEEKDAY(dCalendario[[#This Row],[Fecha]],2) -> 6 | N5: 40 | O5: Progresivas | P5: 10:00 | R5: Liga | S5: =+dCalendario[[#This Row],[Temporada]]&":"&dCalendario[[#This Row],[NºTorneo]] -> 2024:4 | U5: =+dCalendario[[#This Row],[NºTornPunt]]/dCalendario[[#This Row],[NºTorneo]] -> 0.75
A6: 45431 | B6: 2024 | C6: 5 | D6: Lerma | E6: Amarillas | F6: 2 | G6: David | H6: 1 | I6: =+dCalendario[[#This Row],[NºTorneo]]-dCalendario[[#This Row],[RdosQuitar]] -> 4 | J6: =+dCalendario[[#This Row],[Campo]]&"-"&dCalendario[[#This Row],[Barras]] -> Lerma-Amarillas | L6: Clasif | M6: =+WEEKDAY(dCalendario[[#This Row],[Fecha]],2) -> 7 | N6: 40 | O6: Progresivas | P6: 10:00 | Q6: Precio 82€ inlcuye lechazo | R6: Liga | S6: =+dCalendario[[#This Row],[Temporada]]&":"&dCalendario[[#This Row],[NºTorneo]] -> 2024:5 | U6: =+dCalendario[[#This Row],[NºTornPunt]]/dCalendario[[#This Row],[NºTorneo]] -> 0.8
A7: 45444 | B7: 2024 | C7: 6 | D7: Calatayud | E7: Amarillas | F7: 3 | G7: David | H7: 2 | I7: =+dCalendario[[#This Row],[NºTorneo]]-dCalendario[[#This Row],[RdosQuitar]] -> 4 | J7: =+dCalendario[[#This Row],[Campo]]&"-"&dCalendario[[#This Row],[Barras]] -> Calatayud-Amarillas | L7: Clasif | M7: =+WEEKDAY(dCalendario[[#This Row],[Fecha]],2) -> 6 | N7: 40 | O7: Progresivas | P7: 10:30 | R7: Liga | S7: =+dCalendario[[#This Row],[Temporada]]&":"&dCalendario[[#This Row],[NºTorneo]] -> 2024:6 | U7: =+dCalendario[[#This Row],[NºTornPunt]]/dCalendario[[#This Row],[NºTorneo]] -> 0.66666667
A8: 45479 | B8: 2024 | C8: 7 | D8: Palomarejos | E8: Amarillas | F8: 3 | G8: David | H8: 2 | I8: =+dCalendario[[#This Row],[NºTorneo]]-dCalendario[[#This Row],[RdosQuitar]] -> 5 | J8: =+dCalendario[[#This Row],[Campo]]&"-"&dCalendario[[#This Row],[Barras]] -> Palomarejos-Amarillas | L8: Clasif | M8: =+WEEKDAY(dCalendario[[#This Row],[Fecha]],2) -> 6 | N8: 47 | O8: A tiro | P8: 09:45 | R8: Liga | S8: =+dCalendario[[#This Row],[Temporada]]&":"&dCalendario[[#This Row],[NºTorneo]] -> 2024:7 | U8: =+dCalendario[[#This Row],[NºTornPunt]]/dCalendario[[#This Row],[NºTorneo]] -> 0.71428571
A9: 45577 | B9: 2024 | C9: 8 | D9: La Faisanera | E9: Amarillas | F9: 2 | G9: David | H9: 3 | I9: =+dCalendario[[#This Row],[NºTorneo]]-dCalendario[[#This Row],[RdosQuitar]] -> 5 | J9: =+dCalendario[[#This Row],[Campo]]&"-"&dCalendario[[#This Row],[Barras]] -> La Faisanera-Amarillas | L9: Clasif | M9: =+WEEKDAY(dCalendario[[#This Row],[Fecha]],2) -> 6 | N9: 39 | O9: A tiro | P9: 09:30 | R9: Liga | S9: =+dCalendario[[#This Row],[Temporada]]&":"&dCalendario[[#This Row],[NºTorneo]] -> 2024:8 | U9: =+dCalendario[[#This Row],[NºTornPunt]]/dCalendario[[#This Row],[NºTorneo]] -> 0.625
A10: 45612 | B10: 2024 | C10: 9 | D10: Naturávila | E10: Amarillas | F10: 2 | G10: David | H10: 2 | I10: =+dCalendario[[#This Row],[NºTorneo]]-dCalendario[[#This Row],[RdosQuitar]] -> 7 | J10: =+dCalendario[[#This Row],[Campo]]&"-"&dCalendario[[#This Row],[Barras]] -> Naturávila-Amarillas | L10: Clasif | M10: =+WEEKDAY(dCalendario[[#This Row],[Fecha]],2) -> 6 | N10: 30 | O10: A tiro | P10: 09:30 | Q10: Buggy 30€ ; trollet 12€ | R10: Liga | S10: =+dCalendario[[#This Row],[Temporada]]&":"&dCalendario[[#This Row],[NºTorneo]] -> 2024:9 | U10: =+dCalendario[[#This Row],[NºTornPunt]]/dCalendario[[#This Row],[NºTorneo]] -> 0.77777778
A11: 45626 | B11: 2024 | C11: 10 | D11: Layos | E11: Amarillas | F11: 3 | G11: David | H11: 3 | I11: =+dCalendario[[#This Row],[NºTorneo]]-dCalendario[[#This Row],[RdosQuitar]] -> 7 | J11: =+dCalendario[[#This Row],[Campo]]&"-"&dCalendario[[#This Row],[Barras]] -> Layos-Amarillas | L11: Clasif | M11: =+WEEKDAY(dCalendario[[#This Row],[Fecha]],2) -> 6 | N11: 40 | O11: A tiro | P11: 09:30 | Q11: GF+Cocido 65€ | R11: Liga | S11: =+dCalendario[[#This Row],[Temporada]]&":"&dCalendario[[#This Row],[NºTorneo]] -> 2024:10 | U11: =+dCalendario[[#This Row],[NºTornPunt]]/dCalendario[[#This Row],[NºTorneo]] -> 0.7
A12: 45647 | B12: 2024 | C12: 11 | D12: Santander | E12: Amarillas | F12: 1 | G12: David | H12: 3 | I12: =+dCalendario[[#This Row],[NºTorneo]]-dCalendario[[#This Row],[RdosQuitar]] -> 8 | J12: =+dCalendario[[#This Row],[Campo]]&"-"&dCalendario[[#This Row],[Barras]] -> Santander-Amarillas | L12: Clasif | M12: =+WEEKDAY(dCalendario[[#This Row],[Fecha]],2) -> 6 | N12: 71 | O12: A tiro | P12: 10:00 | R12: Liga | S12: =+dCalendario[[#This Row],[Temporada]]&":"&dCalendario[[#This Row],[NºTorneo]] -> 2024:11 | U12: =+dCalendario[[#This Row],[NºTornPunt]]/dCalendario[[#This Row],[NºTorneo]] -> 0.72727273
A13: 45703 | B13: 2025 | C13: 1 | D13: Layos | E13: Amarillas | F13: 2 | G13: David | H13: 0 | I13: =+dCalendario[[#This Row],[NºTorneo]]-dCalendario[[#This Row],[RdosQuitar]] -> 1 | J13: =+dCalendario[[#This Row],[Campo]]&"-"&dCalendario[[#This Row],[Barras]] -> Layos-Amarillas | L13: Hdcp | M13: =+WEEKDAY(dCalendario[[#This Row],[Fecha]],2) -> 6 | N13: 40 | O13: A tiro | P13: 9:00 | Q13: 65€ cocido y picnic | R13: Liga | S13: =+dCalendario[[#This Row],[Temporada]]&":"&dCalendario[[#This Row],[NºTorneo]] -> 2025:1
A14: 45738 | B14: 2025 | C14: 2 | D14: El Encin | E14: Amarillas | F14: 2 | G14: David | H14: 1 | I14: =+dCalendario[[#This Row],[NºTorneo]]-dCalendario[[#This Row],[RdosQuitar]] -> 1 | J14: =+dCalendario[[#This Row],[Campo]]&"-"&dCalendario[[#This Row],[Barras]] -> El Encin-Amarillas | L14: Hdcp | M14: =+WEEKDAY(dCalendario[[#This Row],[Fecha]],2) -> 6 | N14: 56 | O14: Sucesivas | P14: 12:00 | R14: Liga | S14: =+dCalendario[[#This Row],[Temporada]]&":"&dCalendario[[#This Row],[NºTorneo]] -> 2025:2
A15: 45774 | B15: 2025 | C15: 3 | D15: Naturávila | E15: Amarillas | F15: 2 | G15: David | H15: 1 | I15: =+dCalendario[[#This Row],[NºTorneo]]-dCalendario[[#This Row],[RdosQuitar]] -> 2 | J15: =+dCalendario[[#This Row],[Campo]]&"-"&dCalendario[[#This Row],[Barras]] -> Naturávila-Amarillas | L15: Hdcp | M15: =+WEEKDAY(dCalendario[[#This Row],[Fecha]],2) -> 7 | N15: 35 | O15: A tiro | P15: 10:00 | Q15: 25 € bugy | 7€ trolley | 22,50€ comida | R15: Liga | S15: =+dCalendario[[#This Row],[Temporada]]&":"&dCalendario[[#This Row],[NºTorneo]] -> 2025:3
A16: 45794 | B16: 2025 | C16: 4 | D16: Saldaña | E16: Amarillas | F16: 3 | G16: David | H16: 1 | I16: =+dCalendario[[#This Row],[NºTorneo]]-dCalendario[[#This Row],[RdosQuitar]] -> 3 | J16: =+dCalendario[[#This Row],[Campo]]&"-"&dCalendario[[#This Row],[Barras]] -> Saldaña-Amarillas | L16: Clasif | M16: =+WEEKDAY(dCalendario[[#This Row],[Fecha]],2) -> 6 | N16: 44 | O16: A tiro | P16: 9:30 | Q16: 36€ Bugy 16€ Electr 5€ Manual | R16: Liga | S16: =+dCalendario[[#This Row],[Temporada]]&":"&dCalendario[[#This Row],[NºTorneo]] -> 2025:4
A17: 45795 | B17: 2025 | C17: 5 | D17: Lerma | E17: Amarillas | F17: 2 | G17: David | H17: 1 | I17: =+dCalendario[[#This Row],[NºTorneo]]-dCalendario[[#This Row],[RdosQuitar]] -> 4 | J17: =+dCalendario[[#This Row],[Campo]]&"-"&dCalendario[[#This Row],[Barras]] -> Lerma-Amarillas | L17: Clasif | M17: =+WEEKDAY(dCalendario[[#This Row],[Fecha]],2) -> 7 | N17: 44 | O17: Sucesivas | P17: 10:00 | Q17: Entreno 35 € || 36€ Bugy 16€ Electr 5@ Manual | R17: Liga | S17: =+dCalendario[[#This Row],[Temporada]]&":"&dCalendario[[#This Row],[NºTorneo]] -> 2025:5
A18: 45829 | B18: 2025 | C18: 6 | D18: Calatayud | E18: Amarillas | F18: 3 | G18: David | H18: 2 | I18: =+dCalendario[[#This Row],[NºTorneo]]-dCalendario[[#This Row],[RdosQuitar]] -> 4 | J18: =+dCalendario[[#This Row],[Campo]]&"-"&dCalendario[[#This Row],[Barras]] -> Calatayud-Amarillas | L18: Clasif | M18: =+WEEKDAY(dCalendario[[#This Row],[Fecha]],2) -> 6 | N18: 42 | O18: Sucesivas | P18: 9:30 | Q18: Entreno 32 € || Menú 22 € | R18: Liga | S18: =+dCalendario[[#This Row],[Temporada]]&":"&dCalendario[[#This Row],[NºTorneo]] -> 2025:6
A19: 45851 | B19: 2025 | C19: 7 | D19: Palomarejos | E19: Amarillas | F19: 2 | G19: David | H19: 2 | I19: =+dCalendario[[#This Row],[NºTorneo]]-dCalendario[[#This Row],[RdosQuitar]] -> 5 | J19: =+dCalendario[[#This Row],[Campo]]&"-"&dCalendario[[#This Row],[Barras]] -> Palomarejos-Amarillas | L19: Clasif | M19: =+WEEKDAY(dCalendario[[#This Row],[Fecha]],2) -> 7 | N19: 48 | O19: A tiro | P19: 9:30 | R19: Liga | S19: =+dCalendario[[#This Row],[Temporada]]&":"&dCalendario[[#This Row],[NºTorneo]] -> 2025:7
A20: 45920 | B20: 2025 | C20: 8 | D20: Naturávila | E20: Amarillas | F20: 2 | G20: David | H20: 3 | I20: =+dCalendario[[#This Row],[NºTorneo]]-dCalendario[[#This Row],[RdosQuitar]] -> 5 | J20: =+dCalendario[[#This Row],[Campo]]&"-"&dCalendario[[#This Row],[Barras]] -> Naturávila-Amarillas | L20: Clasif | M20: =+WEEKDAY(dCalendario[[#This Row],[Fecha]],2) -> 6 | N20: 22.5 | Q20: 35 € Menú jugador | R20: Liga | S20: =+dCalendario[[#This Row],[Temporada]]&":"&dCalendario[[#This Row],[NºTorneo]] -> 2025:8
A21: 45948 | B21: 2025 | C21: 9 | D21: La Faisanera | E21: Amarillas | F21: 2 | G21: David | H21: 2 | I21: =+dCalendario[[#This Row],[NºTorneo]]-dCalendario[[#This Row],[RdosQuitar]] -> 7 | J21: =+dCalendario[[#This Row],[Campo]]&"-"&dCalendario[[#This Row],[Barras]] -> La Faisanera-Amarillas | L21: Clasif | M21: =+WEEKDAY(dCalendario[[#This Row],[Fecha]],2) -> 6 | N21: 42 | O21: A tiro | P21: 9:30 | R21: Liga | S21: =+dCalendario[[#This Row],[Temporada]]&":"&dCalendario[[#This Row],[NºTorneo]] -> 2025:9
A22: 45983 | B22: 2025 | C22: 10 | D22: Layos | E22: Amarillas | F22: 3 | G22: David | H22: 3 | I22: =+dCalendario[[#This Row],[NºTorneo]]-dCalendario[[#This Row],[RdosQuitar]] -> 7 | J22: =+dCalendario[[#This Row],[Campo]]&"-"&dCalendario[[#This Row],[Barras]] -> Layos-Amarillas | L22: Clasif | M22: =+WEEKDAY(dCalendario[[#This Row],[Fecha]],2) -> 6 | N22: 40 | O22: A tiro | P22: 9:30 | Q22: 65€ cocido y picnic | R22: Liga | S22: =+dCalendario[[#This Row],[Temporada]]&":"&dCalendario[[#This Row],[NºTorneo]] -> 2025:10
A23: 45990 | B23: 2025 | C23: 11 | D23: Olivar | E23: Amarillas | F23: 1 | G23: David | H23: 3 | I23: =+dCalendario[[#This Row],[NºTorneo]]-dCalendario[[#This Row],[RdosQuitar]] -> 8 | J23: =+dCalendario[[#This Row],[Campo]]&"-"&dCalendario[[#This Row],[Barras]] -> Olivar-Amarillas | L23: Clasif | M23: =+WEEKDAY(dCalendario[[#This Row],[Fecha]],2) -> 6 | N23: 55 | O23: Sucesivas | P23: 11:00 | Q23: 65€ Coctel - Entrega de premios | R23: Liga | S23: =+dCalendario[[#This Row],[Temporada]]&":"&dCalendario[[#This Row],[NºTorneo]] -> 2025:11
A24: 46075 | B24: 2026 | C24: 1 | D24: Santander | E24: Amarillas | F24: 2 | G24: David | H24: 0 | I24: =+dCalendario[[#This Row],[NºTorneo]]-dCalendario[[#This Row],[RdosQuitar]] -> 1 | J24: =+dCalendario[[#This Row],[Campo]]&"-"&dCalendario[[#This Row],[Barras]] -> Santander-Amarillas | L24: Hdcp | M24: =+WEEKDAY(dCalendario[[#This Row],[Fecha]],2) -> 7 | R24: Liga | S24: =+dCalendario[[#This Row],[Temporada]]&":"&dCalendario[[#This Row],[NºTorneo]] -> 2026:1
A25: 46102 | B25: 2026 | C25: 2 | D25: Palomarejos | E25: Amarillas | F25: 2 | G25: David | H25: 1 | I25: =+dCalendario[[#This Row],[NºTorneo]]-dCalendario[[#This Row],[RdosQuitar]] -> 1 | J25: =+dCalendario[[#This Row],[Campo]]&"-"&dCalendario[[#This Row],[Barras]] -> Palomarejos-Amarillas | L25: Hdcp | M25: =+WEEKDAY(dCalendario[[#This Row],[Fecha]],2) -> 6 | R25: Liga | S25: =+dCalendario[[#This Row],[Temporada]]&":"&dCalendario[[#This Row],[NºTorneo]] -> 2026:2
A26: 46137 | B26: 2026 | C26: 3 | D26: Naturávila | E26: Amarillas | F26: 2 | G26: David | H26: 1 | I26: =+dCalendario[[#This Row],[NºTorneo]]-dCalendario[[#This Row],[RdosQuitar]] -> 2 | J26: =+dCalendario[[#This Row],[Campo]]&"-"&dCalendario[[#This Row],[Barras]] -> Naturávila-Amarillas | L26: Hdcp | M26: =+WEEKDAY(dCalendario[[#This Row],[Fecha]],2) -> 6 | R26: Liga | S26: =+dCalendario[[#This Row],[Temporada]]&":"&dCalendario[[#This Row],[NºTorneo]] -> 2026:3
A27: 46172 | B27: 2026 | C27: 4 | D27: Saldaña | E27: Amarillas | F27: 3 | G27: David | H27: 1 | I27: =+dCalendario[[#This Row],[NºTorneo]]-dCalendario[[#This Row],[RdosQuitar]] -> 3 | J27: =+dCalendario[[#This Row],[Campo]]&"-"&dCalendario[[#This Row],[Barras]] -> Saldaña-Amarillas | L27: Clasif | M27: =+WEEKDAY(dCalendario[[#This Row],[Fecha]],2) -> 6 | R27: Liga | S27: =+dCalendario[[#This Row],[Temporada]]&":"&dCalendario[[#This Row],[NºTorneo]] -> 2026:4
A28: 46173 | B28: 2026 | C28: 5 | D28: Lerma | E28: Amarillas | F28: 2 | G28: David | H28: 1 | I28: =+dCalendario[[#This Row],[NºTorneo]]-dCalendario[[#This Row],[RdosQuitar]] -> 4 | J28: =+dCalendario[[#This Row],[Campo]]&"-"&dCalendario[[#This Row],[Barras]] -> Lerma-Amarillas | L28: Clasif | M28: =+WEEKDAY(dCalendario[[#This Row],[Fecha]],2) -> 7 | R28: Liga | S28: =+dCalendario[[#This Row],[Temporada]]&":"&dCalendario[[#This Row],[NºTorneo]] -> 2026:5
A29: 46200 | B29: 2026 | C29: 6 | D29: Layos | E29: Amarillas | F29: 2 | G29: David | H29: 2 | I29: =+dCalendario[[#This Row],[NºTorneo]]-dCalendario[[#This Row],[RdosQuitar]] -> 4 | J29: =+dCalendario[[#This Row],[Campo]]&"-"&dCalendario[[#This Row],[Barras]] -> Layos-Amarillas | L29: Clasif | M29: =+WEEKDAY(dCalendario[[#This Row],[Fecha]],2) -> 6 | R29: Liga | S29: =+dCalendario[[#This Row],[Temporada]]&":"&dCalendario[[#This Row],[NºTorneo]] -> 2026:6
A30: 46221 | B30: 2026 | C30: 7 | D30: Desert Spring | E30: Amarillas | F30: 2 | G30: David | H30: 2 | I30: =+dCalendario[[#This Row],[NºTorneo]]-dCalendario[[#This Row],[RdosQuitar]] -> 5 | J30: =+dCalendario[[#This Row],[Campo]]&"-"&dCalendario[[#This Row],[Barras]] -> Desert Spring-Amarillas | L30: Clasif | M30: =+WEEKDAY(dCalendario[[#This Row],[Fecha]],2) -> 6 | R30: Liga | S30: =+dCalendario[[#This Row],[Temporada]]&":"&dCalendario[[#This Row],[NºTorneo]] -> 2026:7
A31: 46222 | B31: 2026 | C31: 8 | D31: Aguilón | E31: Amarillas | F31: 2 | G31: David | H31: 3 | I31: =+dCalendario[[#This Row],[NºTorneo]]-dCalendario[[#This Row],[RdosQuitar]] -> 5 | J31: =+dCalendario[[#This Row],[Campo]]&"-"&dCalendario[[#This Row],[Barras]] -> Aguilón-Amarillas | L31: Clasif | M31: =+WEEKDAY(dCalendario[[#This Row],[Fecha]],2) -> 7 | R31: Liga | S31: =+dCalendario[[#This Row],[Temporada]]&":"&dCalendario[[#This Row],[NºTorneo]] -> 2026:8
A32: 46277 | B32: 2026 | C32: 9 | D32: La Faisanera | E32: Amarillas | F32: 3 | G32: David | H32: 3 | I32: =+dCalendario[[#This Row],[NºTorneo]]-dCalendario[[#This Row],[RdosQuitar]] -> 6 | J32: =+dCalendario[[#This Row],[Campo]]&"-"&dCalendario[[#This Row],[Barras]] -> La Faisanera-Amarillas | L32: Clasif | M32: =+WEEKDAY(dCalendario[[#This Row],[Fecha]],2) -> 6 | R32: Liga | S32: =+dCalendario[[#This Row],[Temporada]]&":"&dCalendario[[#This Row],[NºTorneo]] -> 2026:9
A33: 46313 | B33: 2026 | C33: 10 | D33: Naturávila | E33: Amarillas | F33: 2 | G33: David | H33: 3 | I33: =+dCalendario[[#This Row],[NºTorneo]]-dCalendario[[#This Row],[RdosQuitar]] -> 7 | J33: =+dCalendario[[#This Row],[Campo]]&"-"&dCalendario[[#This Row],[Barras]] -> Naturávila-Amarillas | L33: Clasif | M33: =+WEEKDAY(dCalendario[[#This Row],[Fecha]],2) -> 7 | R33: Liga | S33: =+dCalendario[[#This Row],[Temporada]]&":"&dCalendario[[#This Row],[NºTorneo]] -> 2026:10
A34: 46348 | B34: 2026 | C34: 11 | D34: El Encin | E34: Amarillas | F34: 3 | G34: David | H34: 3 | I34: =+dCalendario[[#This Row],[NºTorneo]]-dCalendario[[#This Row],[RdosQuitar]] -> 8 | J34: =+dCalendario[[#This Row],[Campo]]&"-"&dCalendario[[#This Row],[Barras]] -> El Encin-Amarillas | L34: Clasif | M34: =+WEEKDAY(dCalendario[[#This Row],[Fecha]],2) -> 7 | R34: Liga | S34: =+dCalendario[[#This Row],[Temporada]]&":"&dCalendario[[#This Row],[NºTorneo]] -> 2026:11
A35: 46375 | B35: 2026 | C35: 12 | D35: Santander | E35: Amarillas | F35: 1 | G35: David | H35: 4 | I35: =+dCalendario[[#This Row],[NºTorneo]]-dCalendario[[#This Row],[RdosQuitar]] -> 8 | J35: =+dCalendario[[#This Row],[Campo]]&"-"&dCalendario[[#This Row],[Barras]] -> Santander-Amarillas | L35: Clasif | M35: =+WEEKDAY(dCalendario[[#This Row],[Fecha]],2) -> 6 | R35: Liga | S35: =+dCalendario[[#This Row],[Temporada]]&":"&dCalendario[[#This Row],[NºTorneo]] -> 2026:12

Sheet Puntos Equipos
A1: Temporada | B1: Pos | C1: Puntos | F1: Temporada | G1: Jugador Nº | H1: Puntos
A2: 2024 | B2: 1 | C2: 500 | F2: 2025 | G2: 1 | H2: 10
A3: 2024 | B3: 2 | C3: 400 | F3: 2025 | G3: 2 | H3: 20
A4: 2024 | B4: 3 | C4: 300 | F4: 2025 | G4: 3 | H4: 30
A5: 2024 | B5: 4 | C5: 200 | F5: 2025 | G5: 4 | H5: 40
A6: 2024 | B6: 5 | C6: =+C5-25 -> 175 | F6: 2026 | G6: 1 | H6: 10
A7: 2024 | B7: 6 | C7: =+C6-25 -> 150 | F7: 2026 | G7: 2 | H7: 20
A8: 2024 | B8: 7 | C8: =+C7-25 -> 125 | F8: 2026 | G8: 3 | H8: 30
A9: 2024 | B9: 8 | C9: =+C8-25 -> 100 | F9: 2026 | G9: 4 | H9: 40
A10: 2024 | B10: 9 | C10: =+C9-25 -> 75 | F10: 2026 | G10: 5 | H10: 50
A11: 2025 | B11: 1 | C11: 500
A12: 2025 | B12: 2 | C12: 400
A13: 2025 | B13: 3 | C13: 300
A14: 2025 | B14: 4 | C14: 200
A15: 2025 | B15: 5 | C15: =+C14-25 -> 175
A16: 2025 | B16: 6 | C16: =+C15-25 -> 150
A17: 2025 | B17: 7 | C17: =+C16-25 -> 125
A18: 2025 | B18: 8 | C18: =+C17-25 -> 100
A19: 2025 | B19: 9 | C19: =+C18-25 -> 75
A20: 2026 | B20: 1 | C20: 500
A21: 2026 | B21: 2 | C21: 400
A22: 2026 | B22: 3 | C22: 300
A23: 2026 | B23: 4 | C23: 200
A24: 2026 | B24: 5 | C24: =+C23-25 -> 175
A25: 2026 | B25: 6 | C25: =+C24-25 -> 150
A26: 2026 | B26: 7 | C26: =+C25-25 -> 125
A27: 2026 | B27: 8 | C27: =+C26-25 -> 100
A28: 2026 | B28: 9 | C28: =+C27-25 -> 75

Sheet dTipoCalculo
A1: Calculo | B1: IdCalculo
A2: Neto | B2: 1
A3: Bruto | B3: 2

Sheet Descalificados
A1: Temporada | B1: Nº Torneo | C1: Nombre | D1: Motivo

Sheet dHandicapActual
A1: Fecha | B1: Nombre | C1: HandicapActual | D1: Licencia | E1: HandicapAnterior | F1: Mote | G1: Nombre y Apellidos | H1: Fecha:Jugador
A2: 45697 | B2: Nacho Gonzalez | C2: 4.7 | D2: CME6076737 | E2: 4.7 | F2: Nacho | G2: Ignacio González Salvador | H2: 09/02/2025:Nacho Gonzalez
A3: 45699 | B3: Nacho Gonzalez | C3: 4.7 | D3: CME6076737 | E3: 4.7 | F3: Nacho | G3: Ignacio González Salvador | H3: 11/02/2025:Nacho Gonzalez
A4: 45697 | B4: Ignacio Cadarso | C4: 6.8 | D4: CME6501940 | E4: 6.8 | F4: Ignacio | G4: Ignacio Cadarso Amador | H4: 09/02/2025:Ignacio Cadarso
A5: 45699 | B5: Ignacio Cadarso | C5: 6.8 | D5: CME6501940 | E5: 6.8 | F5: Ignacio | G5: Ignacio Cadarso Amador | H5: 11/02/2025:Ignacio Cadarso
A6: 45697 | B6: Alfonso Hidalgo | C6: 12.3 | D6: CME6255829 | E6: 12.3 | F6: Alfonso | G6: Alfonso Hidalgo Lopez de Ayala | H6: 09/02/2025:Alfonso Hidalgo
A7: 45699 | B7: Alfonso Hidalgo | C7: 12.3 | D7: CME6255829 | E7: 12.3 | F7: Alfonso | G7: Alfonso Hidalgo Lopez de Ayala | H7: 11/02/2025:Alfonso Hidalgo
A8: 45697 | B8: Francisco Alvarez | C8: 15.7 | D8: CME6389026 | E8: 15.5 | F8: Paco | G8: Francisco Alvarez Oliva | H8: 09/02/2025:Francisco Alvarez
A9: 45699 | B9: Francisco Alvarez | C9: 15.7 | D9: CME6389026 | E9: 15.5 | F9: Paco | G9: Francisco Alvarez Oliva | H9: 11/02/2025:Francisco Alvarez
A10: 45697 | B10: Alvaro Aguirre | C10: 6 | D10: CME6628917 | E10: 5.7 | F10: Gifu | G10: Alvaro Aguirre Rodriguez | H10: 09/02/2025:Alvaro Aguirre
A11: 45699 | B11: Alvaro Aguirre | C11: 6 | D11: CME6628917 | E11: 5.7 | F11: Gifu | G11: Alvaro Aguirre Rodriguez | H11: 11/02/2025:Alvaro Aguirre
A12: 45697 | B12: José Pablo Guil | C12: 7 | D12: CME6089043 | E12: 6.8 | F12: JP | G12: José Pablo Guil Salvador | H12: 09/02/2025:José Pablo Guil
A13: 45699 | B13: José Pablo Guil | C13: 7 | D13: CME6089043 | E13: 6.8 | F13: JP | G13: José Pablo Guil Salvador | H13: 11/02/2025:José Pablo Guil
... A662: 45979 | B662: Jaime de la Cal | C662: 9.8 | D662: CM00417892 | E662: 10.8 | F662: Jaime | G662: Jaime de la Cal | H662: 18/11/2025:Jaime de la Cal

Sheet Handicaps
A1: Fecha | B1: Nombre | C1: Handicap | D1: Cat | E1: Tipo | F1: __PowerAppsId__ | G1: Maximo | H1: CodUltHand | I1: UltHandMote | J1: Ranking | K1: Pos | L1: Orden | M1: Columna1 | N1: Columna2
A2: 43309 | B2: Alfonso Hidalgo | C2: 8.3 | D2: 2 | E2: Cuart | F2: 1d166cbc-8950-41ba-b862-b7c1e4a278c2 | G2: =+IF(dHdcp[[#This Row],[Fecha]]=MAX(dHdcp[Fecha]),1,0) -> 0 | H2: =+dHdcp[[#This Row],[Maximo]]&":"&dHdcp[[#This Row],[Nombre]] -> 0:Alfonso Hidalgo | I2: =+dHdcp[[#This Row],[Maximo]]&":"&_xlfn.XLOOKUP(dHdcp[[#This Row],[Nombre]],dJugador[Nombre],dJugador[Mote],"",0) -> 0:Alfonso | J2: =+IF(dHdcp[[#This Row],[Maximo]]=0,"",_xlfn.RANK.EQ(dHdcp[[#This Row],[Handicap]],dHdcp[Handicap],1)) | K2: =IFERROR(+_xlfn.RANK.EQ(dHdcp[[#This Row],[Ranking]],dHdcp[Ranking],1),"") | M2: =+dHdcp[[#This Row],[Fecha]]&":"&dHdcp[[#This Row],[Nombre]] -> 43309:Alfonso Hidalgo | N2: =+COUNTIF(dHdcp[Columna1],dHdcp[[#This Row],[Columna1]]) -> 1
A3: 43309 | B3: Alvaro Aguirre | C3: 5.4 | D3: 2 | E3: Cuart | F3: 79b71327-c489-4e4e-8aee-04ceed86c7f1 | G3: =+IF(dHdcp[[#This Row],[Fecha]]=MAX(dHdcp[Fecha]),1,0) -> 0 | H3: =+dHdcp[[#This Row],[Maximo]]&":"&dHdcp[[#This Row],[Nombre]] -> 0:Alvaro Aguirre | I3: =+dHdcp[[#This Row],[Maximo]]&":"&_xlfn.XLOOKUP(dHdcp[[#This Row],[Nombre]],dJugador[Nombre],dJugador[Mote],"",0) -> 0:Gifu | J3: =+IF(dHdcp[[#This Row],[Maximo]]=0,"",_xlfn.RANK.EQ(dHdcp[[#This Row],[Handicap]],dHdcp[Handicap],1)) | K3: =IFERROR(+_xlfn.RANK.EQ(dHdcp[[#This Row],[Ranking]],dHdcp[Ranking],1),"") | M3: =+dHdcp[[#This Row],[Fecha]]&":"&dHdcp[[#This Row],[Nombre]] -> 43309:Alvaro Aguirre | N3: =+COUNTIF(dHdcp[Columna1],dHdcp[[#This Row],[Columna1]]) -> 1
A4: 43309 | B4: Alvaro Nieto | C4: 15.3 | D4: 3 | E4: Cuart | F4: bff6c657-8cb3-42d5-a667-3afecb8b6018 | G4: =+IF(dHdcp[[#This Row],[Fecha]]=MAX(dHdcp[Fecha]),1,0) -> 0 | H4: =+dHdcp[[#This Row],[Maximo]]&":"&dHdcp[[#This Row],[Nombre]] -> 0:Alvaro Nieto | I4: =+dHdcp[[#This Row],[Maximo]]&":"&_xlfn.XLOOKUP(dHdcp[[#This Row],[Nombre]],dJugador[Nombre],dJugador[Mote],"",0) -> 0:Alvaro | J4: =+IF(dHdcp[[#This Row],[Maximo]]=0,"",_xlfn.RANK.EQ(dHdcp[[#This Row],[Handicap]],dHdcp[Handicap],1)) | K4: =IFERROR(+_xlfn.RANK.EQ(dHdcp[[#This Row],[Ranking]],dHdcp[Ranking],1),"") | M4: =+dHdcp[[#This Row],[Fecha]]&":"&dHdcp[[#This Row],[Nombre]] -> 43309:Alvaro Nieto | N4: =+COUNTIF(dHdcp[Columna1],dHdcp[[#This Row],[Columna1]]) -> 1
A5: 43309 | B5: Angel Hernandez | C5: 6.1 | D5: 2 | E5: Cuart | F5: f4da60f7-6556-4cec-b67f-127c58a42ed7 | G5: =+IF(dHdcp[[#This Row],[Fecha]]=MAX(dHdcp[Fecha]),1,0) -> 0 | H5: =+dHdcp[[#This Row],[Maximo]]&":"&dHdcp[[#This Row],[Nombre]] -> 0:Angel Hernandez | I5: =+dHdcp[[#This Row],[Maximo]]&":"&_xlfn.XLOOKUP(dHdcp[[#This Row],[Nombre]],dJugador[Nombre],dJugador[Mote],"",0) -> 0:Angel | J5: =+IF(dHdcp[[#This Row],[Maximo]]=0,"",_xlfn.RANK.EQ(dHdcp[[#This Row],[Handicap]],dHdcp[Handicap],1)) | K5: =IFERROR(+_xlfn.RANK.EQ(dHdcp[[#This Row],[Ranking]],dHdcp[Ranking],1),"") | M5: =+dHdcp[[#This Row],[Fecha]]&":"&dHdcp[[#This Row],[Nombre]] -> 43309:Angel Hernandez | N5: =+COUNTIF(dHdcp[Columna1],dHdcp[[#This Row],[Columna1]]) -> 1
A6: 43309 | B6: David Sequera | C6: 12.8 | D6: 3 | E6: Cuart | F6: 9cf0222d-4b91-46c6-9a68-0333d0effab0 | G6: =+IF(dHdcp[[#This Row],[Fecha]]=MAX(dHdcp[Fecha]),1,0) -> 0 | H6: =+dHdcp[[#This Row],[Maximo]]&":"&dHdcp[[#This Row],[Nombre]] -> 0:David Sequera | I6: =+dHdcp[[#This Row],[Maximo]]&":"&_xlfn.XLOOKUP(dHdcp[[#This Row],[Nombre]],dJugador[Nombre],dJugador[Mote],"",0) -> 0:David | J6: =+IF(dHdcp[[#This Row],[Maximo]]=0,"",_xlfn.RANK.EQ(dHdcp[[#This Row],[Handicap]],dHdcp[Handicap],1)) | K6: =IFERROR(+_xlfn.RANK.EQ(dHdcp[[#This Row],[Ranking]],dHdcp[Ranking],1),"") | M6: =+dHdcp[[#This Row],[Fecha]]&":"&dHdcp[[#This Row],[Nombre]] -> 43309:David Sequera | N6: =+COUNTIF(dHdcp[Columna1],dHdcp[[#This Row],[Columna1]]) -> 1
A7: 43309 | B7: Francisco Alvarez | C7: 17.2 | D7: 3 | E7: Cuart | F7: bd5a876f-4c32-47f2-95ca-3cf9616fc6f4 | G7: =+IF(dHdcp[[#This Row],[Fecha]]=MAX(dHdcp[Fecha]),1,0) -> 0 | H7: =+dHdcp[[#This Row],[Maximo]]&":"&dHdcp[[#This Row],[Nombre]] -> 0:Francisco Alvarez | I7: =+dHdcp[[#This Row],[Maximo]]&":"&_xlfn.XLOOKUP(dHdcp[[#This Row],[Nombre]],dJugador[Nombre],dJugador[Mote],"",0) -> 0:Paco | J7: =+IF(dHdcp[[#This Row],[Maximo]]=0,"",_xlfn.RANK.EQ(dHdcp[[#This Row],[Handicap]],dHdcp[Handicap],1)) | K7: =IFERROR(+_xlfn.RANK.EQ(dHdcp[[#This Row],[Ranking]],dHdcp[Ranking],1),"") | M7: =+dHdcp[[#This Row],[Fecha]]&":"&dHdcp[[#This Row],[Nombre]] -> 43309:Francisco Alvarez | N7: =+COUNTIF(dHdcp[Columna1],dHdcp[[#This Row],[Columna1]]) -> 1
A8: 43309 | B8: Francisco Hidalgo | C8: 13 | D8: 3 | E8: Cuart | F8: 0fd1f4e5-6f7c-475d-b69a-12eb09fbf780 | G8: =+IF(dHdcp[[#This Row],[Fecha]]=MAX(dHdcp[Fecha]),1,0) -> 0 | H8: =+dHdcp[[#This Row],[Maximo]]&":"&dHdcp[[#This Row],[Nombre]] -> 0:Francisco Hidalgo | I8: =+dHdcp[[#This Row],[Maximo]]&":"&_xlfn.XLOOKUP(dHdcp[[#This Row],[Nombre]],dJugador[Nombre],dJugador[Mote],"",0) -> 0:Fran | J8: =+IF(dHdcp[[#This Row],[Maximo]]=0,"",_xlfn.RANK.EQ(dHdcp[[#This Row],[Handicap]],dHdcp[Handicap],1)) | K8: =IFERROR(+_xlfn.RANK.EQ(dHdcp[[#This Row],[Ranking]],dHdcp[Ranking],1),"") | M8: =+dHdcp[[#This Row],[Fecha]]&":"&dHdcp[[#This Row],[Nombre]] -> 43309:Francisco Hidalgo | N8: =+COUNTIF(dHdcp[Columna1],dHdcp[[#This Row],[Columna1]]) -> 1
A9: 43309 | B9: GLEZ JUAN JOSÉ | C9: 16.6 | D9: 3 | E9: Cuart | F9: e587dc88-50d5-4ace-9960-9c5bb3fcb3a5 | G9: =+IF(dHdcp[[#This Row],[Fecha]]=MAX(dHdcp[Fecha]),1,0) -> 0 | H9: =+dHdcp[[#This Row],[Maximo]]&":"&dHdcp[[#This Row],[Nombre]] -> 0:GLEZ JUAN JOSÉ | I9: =+dHdcp[[#This Row],[Maximo]]&":"&_xlfn.XLOOKUP(dHdcp[[#This Row],[Nombre]],dJugador[Nombre],dJugador[Mote],"",0) -> 0:Juanjo | J9: =+IF(dHdcp[[#This Row],[Maximo]]=0,"",_xlfn.RANK.EQ(dHdcp[[#This Row],[Handicap]],dHdcp[Handicap],1)) | K9: =IFERROR(+_xlfn.RANK.EQ(dHdcp[[#This Row],[Ranking]],dHdcp[Ranking],1),"") | M9: =+dHdcp[[#This Row],[Fecha]]&":"&dHdcp[[#This Row],[Nombre]] -> 43309:GLEZ JUAN JOSÉ | N9: =+COUNTIF(dHdcp[Columna1],dHdcp[[#This Row],[Columna1]]) -> 1
A10: 43309 | B10: Ignacio Cadarso | C10: 7.3 | D10: 2 | E10: Cuart | F10: 2f34515d-633d-4eea-83c5-f98a6c893967 | G10: =+IF(dHdcp[[#This Row],[Fecha]]=MAX(dHdcp[Fecha]),1,0) -> 0 | H10: =+dHdcp[[#This Row],[Maximo]]&":"&dHdcp[[#This Row],[Nombre]] -> 0:Ignacio Cadarso | I10: =+dHdcp[[#This Row],[Maximo]]&":"&_xlfn.XLOOKUP(dHdcp[[#This Row],[Nombre]],dJugador[Nombre],dJugador[Mote],"",0) -> 0:Ignacio | J10: =+IF(dHdcp[[#This Row],[Maximo]]=0,"",_xlfn.RANK.EQ(dHdcp[[#This Row],[Handicap]],dHdcp[Handicap],1)) | K10: =IFERROR(+_xlfn.RANK.EQ(dHdcp[[#This Row],[Ranking]],dHdcp[Ranking],1),"") | M10: =+dHdcp[[#This Row],[Fecha]]&":"&dHdcp[[#This Row],[Nombre]] -> 43309:Ignacio Cadarso | N10: =+COUNTIF(dHdcp[Columna1],dHdcp[[#This Row],[Columna1]]) -> 1
A11: 43309 | B11: Iñigo Rosas | C11: 13.3 | D11: 3 | E11: Cuart | F11: 07c4d00c-33f1-4d99-bcbe-a5719fd91e28 | G11: =+IF(dHdcp[[#This Row],[Fecha]]=MAX(dHdcp[Fecha]),1,0) -> 0 | H11: =+dHdcp[[#This Row],[Maximo]]&":"&dHdcp[[#This Row],[Nombre]] -> 0:Iñigo Rosas | I11: =+dHdcp[[#This Row],[Maximo]]&":"&_xlfn.XLOOKUP(dHdcp[[#This Row],[Nombre]],dJugador[Nombre],dJugador[Mote],"",0) -> 0: | J11: =+IF(dHdcp[[#This Row],[Maximo]]=0,"",_xlfn.RANK.EQ(dHdcp[[#This Row],[Handicap]],dHdcp[Handicap],1)) | K11: =IFERROR(+_xlfn.RANK.EQ(dHdcp[[#This Row],[Ranking]],dHdcp[Ranking],1),"") | M11: =+dHdcp[[#This Row],[Fecha]]&":"&dHdcp[[#This Row],[Nombre]] -> 43309:Iñigo Rosas | N11: =+COUNTIF(dHdcp[Columna1],dHdcp[[#This Row],[Columna1]]) -> 1
A12: 43309 | B12: J. Enrique Gonzalez | C12: 19 | D12: 4 | E12: Cuart | F12: e609a2cd-d4d2-4130-b877-c56466bb8fc7 | G12: =+IF(dHdcp[[#This Row],[Fecha]]=MAX(dHdcp[Fecha]),1,0) -> 0 | H12: =+dHdcp[[#This Row],[Maximo]]&":"&dHdcp[[#This Row],[Nombre]] -> 0:J. Enrique Gonzalez | I12: =+dHdcp[[#This Row],[Maximo]]&":"&_xlfn.XLOOKUP(dHdcp[[#This Row],[Nombre]],dJugador[Nombre],dJugador[Mote],"",0) -> 0:Kike | J12: =+IF(dHdcp[[#This Row],[Maximo]]=0,"",_xlfn.RANK.EQ(dHdcp[[#This Row],[Handicap]],dHdcp[Handicap],1)) | K12: =IFERROR(+_xlfn.RANK.EQ(dHdcp[[#This Row],[Ranking]],dHdcp[Ranking],1),"") | M12: =+dHdcp[[#This Row],[Fecha]]&":"&dHdcp[[#This Row],[Nombre]] -> 43309:J. Enrique Gonzalez | N12: =+COUNTIF(dHdcp[Columna1],dHdcp[[#This Row],[Columna1]]) -> 1
A13: 43309 | B13: Javier Cervera | C13: 12.9 | D13: 3 | E13: Cuart | F13: cbbca621-b918-4ef7-a741-caeb430a3c03 | G13: =+IF(dHdcp[[#This Row],[Fecha]]=MAX(dHdcp[Fecha]),1,0) -> 0 | H13: =+dHdcp[[#This Row],[Maximo]]&":"&dHdcp[[#This Row],[Nombre]] -> 0:Javier Cervera | I13: =+dHdcp[[#This Row],[Maximo]]&":"&_xlfn.XLOOKUP(dHdcp[[#This Row],[Nombre]],dJugador[Nombre],dJugador[Mote],"",0) -> 0:Virus | J13: =+IF(dHdcp[[#This Row],[Maximo]]=0,"",_xlfn.RANK.EQ(dHdcp[[#This Row],[Handicap]],dHdcp[Handicap],1)) | K13: =IFERROR(+_xlfn.RANK.EQ(dHdcp[[#This Row],[Ranking]],dHdcp[Ranking],1),"") | M13: =+dHdcp[[#This Row],[Fecha]]&":"&dHdcp[[#This Row],[Nombre]] -> 43309:Javier Cervera | N13: =+COUNTIF(dHdcp[Columna1],dHdcp[[#This Row],[Columna1]]) -> 1
... A555: 43879 | B555: Pablo Munitiz | C555: 13.4 | D555: 3 | E555: Cuart | F555: f955fd0e-1158-4261-95c3-bcf5b62380dc | G555: =+IF(dHdcp[[#This Row],[Fecha]]=MAX(dHdcp[Fecha]),1,0) -> 0 | H555: =+dHdcp[[#This Row],[Maximo]]&":"&dHdcp[[#This Row],[Nombre]] -> 0:Pablo Munitiz | I555: =+dHdcp[[#This Row],[Maximo]]&":"&_xlfn.XLOOKUP(dHdcp[[#This Row],[Nombre]],dJugador[Nombre],dJugador[Mote],"",0) -> 0:Muni | J555: =+IF(dHdcp[[#This Row],[Maximo]]=0,"",_xlfn.RANK.EQ(dHdcp[[#This Row],[Handicap]],dHdcp[Handicap],1)) | K555: =IFERROR(+_xlfn.RANK.EQ(dHdcp[[#This Row],[Ranking]],dHdcp[Ranking],1),"") | M555: =+dHdcp[[#This Row],[Fecha]]&":"&dHdcp[[#This Row],[Nombre]] -> 43879:Pablo Munitiz | N555: =+COUNTIF(dHdcp[Columna1],dHdcp[[#This Row],[Columna1]]) -> 2
A556: 43992 | B556: Alfonso Hidalgo | C556: 9.3 | D556: =+VLOOKUP(dHdcp[[#This Row],[Handicap]],'Categoría Hdcap'!$B$2:$E$7,4) -> 2 | E556: Fed | F556: 86d8a859-5801-40a9-bd9f-f762b507d634 | G556: =+IF(dHdcp[[#This Row],[Fecha]]=MAX(dHdcp[Fecha]),1,0) -> 0 | H556: =+dHdcp[[#This Row],[Maximo]]&":"&dHdcp[[#This Row],[Nombre]] -> 0:Alfonso Hidalgo | I556: =+dHdcp[[#This Row],[Maximo]]&":"&_xlfn.XLOOKUP(dHdcp[[#This Row],[Nombre]],dJugador[Nombre],dJugador[Mote],"",0) -> 0:Alfonso | J556: =+IF(dHdcp[[#This Row],[Maximo]]=0,"",_xlfn.RANK.EQ(dHdcp[[#This Row],[Handicap]],dHdcp[Handicap],1)) | K556: =IFERROR(+_xlfn.RANK.EQ(dHdcp[[#This Row],[Ranking]],dHdcp[Ranking],1),"") | M556: =+dHdcp[[#This Row],[Fecha]]&":"&dHdcp[[#This Row],[Nombre]] -> 43992:Alfonso Hidalgo | N556: =+COUNTIF(dHdcp[Columna1],dHdcp[[#This Row],[Columna1]]) -> 2
A557: 43992 | B557: Alfonso Hidalgo | C557: 8 | D557: 2 | E557: Cuart | F557: 718ca4ff-75ed-4b98-91bf-e33297bbf254 | G557: =+IF(dHdcp[[#This Row],[Fecha]]=MAX(dHdcp[Fecha]),1,0) -> 0 | H557: =+dHdcp[[#This Row],[Maximo]]&":"&dHdcp[[#This Row],[Nombre]] -> 0:Alfonso Hidalgo | I557: =+dHdcp[[#This Row],[Maximo]]&":"&_xlfn.XLOOKUP(dHdcp[[#This Row],[Nombre]],dJugador[Nombre],dJugador[Mote],"",0) -> 0:Alfonso | J557: =+IF(dHdcp[[#This Row],[Maximo]]=0,"",_xlfn.RANK.EQ(dHdcp[[#This Row],[Handicap]],dHdcp[Handicap],1)) | K557: =IFERROR(+_xlfn.RANK.EQ(dHdcp[[#This Row],[Ranking]],dHdcp[Ranking],1),"") | M557: =+dHdcp[[#This Row],[Fecha]]&":"&dHdcp[[#This Row],[Nombre]] -> 43992:Alfonso Hidalgo | N557: =+COUNTIF(dHdcp[Columna1],dHdcp[[#This Row],[Columna1]]) -> 2
A558: 43992 | B558: Alvaro Aguirre | C558: 4.8 | D558: =+VLOOKUP(dHdcp[[#This Row],[Handicap]],'Categoría Hdcap'!$B$2:$E$7,4) -> 2 | E558: Fed | F558: 1d102209-1958-4b1b-8815-205fb806fb8a | G558: =+IF(dHdcp[[#This Row],[Fecha]]=MAX(dHdcp[Fecha]),1,0) -> 0 | H558: =+dHdcp[[#This Row],[Maximo]]&":"&dHdcp[[#This Row],[Nombre]] -> 0:Alvaro Aguirre | I558: =+dHdcp[[#This Row],[Maximo]]&":"&_xlfn.XLOOKUP(dHdcp[[#This Row],[Nombre]],dJugador[Nombre],dJugador[Mote],"",0) -> 0:Gifu | J558: =+IF(dHdcp[[#This Row],[Maximo]]=0,"",_xlfn.RANK.EQ(dHdcp[[#This Row],[Handicap]],dHdcp[Handicap],1)) | K558: =IFERROR(+_xlfn.RANK.EQ(dHdcp[[#This Row],[Ranking]],dHdcp[Ranking],1),"") | M558: =+dHdcp[[#This Row],[Fecha]]&":"&dHdcp[[#This Row],[Nombre]] -> 43992:Alvaro Aguirre | N558: =+COUNTIF(dHdcp[Columna1],dHdcp[[#This Row],[Columna1]]) -> 2
A559: 43992 | B559: Alvaro Aguirre | C559: 4.8 | D559: 2 | E559: Cuart | F559: 22254c03-5478-4eba-b402-d0b060320d58 | G559: =+IF(dHdcp[[#This Row],[Fecha]]=MAX(dHdcp[Fecha]),1,0) -> 0 | H559: =+dHdcp[[#This Row],[Maximo]]&":"&dHdcp[[#This Row],[Nombre]] -> 0:Alvaro Aguirre | I559: =+dHdcp[[#This Row],[Maximo]]&":"&_xlfn.XLOOKUP(dHdcp[[#This Row],[Nombre]],dJugador[Nombre],dJugador[Mote],"",0) -> 0:Gifu | J559: =+IF(dHdcp[[#This Row],[Maximo]]=0,"",_xlfn.RANK.EQ(dHdcp[[#This Row],[Handicap]],dHdcp[Handicap],1)) | K559: =IFERROR(+_xlfn.RANK.EQ(dHdcp[[#This Row],[Ranking]],dHdcp[Ranking],1),"") | M559: =+dHdcp[[#This Row],[Fecha]]&":"&dHdcp[[#This Row],[Nombre]] -> 43992:Alvaro Aguirre | N559: =+COUNTIF(dHdcp[Columna1],dHdcp[[#This Row],[Columna1]]) -> 2
A560: 43992 | B560: Alvaro Nieto | C560: 14.1 | D560: =+VLOOKUP(dHdcp[[#This Row],[Handicap]],'Categoría Hdcap'!$B$2:$E$7,4) -> 3 | E560: Fed | F560: 7fae8c8d-0917-44d0-bd0a-fa777cdbbd92 | G560: =+IF(dHdcp[[#This Row],[Fecha]]=MAX(dHdcp[Fecha]),1,0) -> 0 | H560: =+dHdcp[[#This Row],[Maximo]]&":"&dHdcp[[#This Row],[Nombre]] -> 0:Alvaro Nieto | I560: =+dHdcp[[#This Row],[Maximo]]&":"&_xlfn.XLOOKUP(dHdcp[[#This Row],[Nombre]],dJugador[Nombre],dJugador[Mote],"",0) -> 0:Alvaro | J560: =+IF(dHdcp[[#This Row],[Maximo]]=0,"",_xlfn.RANK.EQ(dHdcp[[#This Row],[Handicap]],dHdcp[Handicap],1)) | K560: =IFERROR(+_xlfn.RANK.EQ(dHdcp[[#This Row],[Ranking]],dHdcp[Ranking],1),"") | M560: =+dHdcp[[#This Row],[Fecha]]&":"&dHdcp[[#This Row],[Nombre]] -> 43992:Alvaro Nieto | N560: =+COUNTIF(dHdcp[Columna1],dHdcp[[#This Row],[Columna1]]) -> 2
A561: 43992 | B561: Alvaro Nieto | C561: 13.2 | D561: 3 | E561: Cuart | F561: d1bc72ab-1057-4283-b2ca-f9e0d801a655 | G561: =+IF(dHdcp[[#This Row],[Fecha]]=MAX(dHdcp[Fecha]),1,0) -> 0 | H561: =+dHdcp[[#This Row],[Maximo]]&":"&dHdcp[[#This Row],[Nombre]] -> 0:Alvaro Nieto | I561: =+dHdcp[[#This Row],[Maximo]]&":"&_xlfn.XLOOKUP(dHdcp[[#This Row],[Nombre]],dJugador[Nombre],dJugador[Mote],"",0) -> 0:Alvaro | J561: =+IF(dHdcp[[#This Row],[Maximo]]=0,"",_xlfn.RANK.EQ(dHdcp[[#This Row],[Handicap]],dHdcp[Handicap],1)) | K561: =IFERROR(+_xlfn.RANK.EQ(dHdcp[[#This Row],[Ranking]],dHdcp[Ranking],1),"") | M561: =+dHdcp[[#This Row],[Fecha]]&":"&dHdcp[[#This Row],[Nombre]] -> 43992:Alvaro Nieto | N561: =+COUNTIF(dHdcp[Columna1],dHdcp[[#This Row],[Columna1]]) -> 2
A562: 43992 | B562: Angel Hernandez | C562: 8.3 | D562: =+VLOOKUP(dHdcp[[#This Row],[Handicap]],'Categoría Hdcap'!$B$2:$E$7,4) -> 2 | E562: Fed | F562: d2967550-b78b-40c3-9832-16e4c2c38769 | G562: =+IF(dHdcp[[#This Row],[Fecha]]=MAX(dHdcp[Fecha]),1,0) -> 0 | H562: =+dHdcp[[#This Row],[Maximo]]&":"&dHdcp[[#This Row],[Nombre]] -> 0:Angel Hernandez | I562: =+dHdcp[[#This Row],[Maximo]]&":"&_xlfn.XLOOKUP(dHdcp[[#This Row],[Nombre]],dJugador[Nombre],dJugador[Mote],"",0) -> 0:Angel | J562: =+IF(dHdcp[[#This Row],[Maximo]]=0,"",_xlfn.RANK.EQ(dHdcp[[#This Row],[Handicap]],dHdcp[Handicap],1)) | K562: =IFERROR(+_xlfn.RANK.EQ(dHdcp[[#This Row],[Ranking]],dHdcp[Ranking],1),"") | M562: =+dHdcp[[#This Row],[Fecha]]&":"&dHdcp[[#This Row],[Nombre]] -> 43992:Angel Hernandez | N562: =+COUNTIF(dHdcp[Columna1],dHdcp[[#This Row],[Columna1]]) -> 2
A563: 43992 | B563: Angel Hernandez | C563: 6.5 | D563: 2 | E563: Cuart | F563: 44a64815-9a06-430a-860c-01bed812247f | G563: =+IF(dHdcp[[#This Row],[Fecha]]=MAX(dHdcp[Fecha]),1,0) -> 0 | H563: =+dHdcp[[#This Row],[Maximo]]&":"&dHdcp[[#This Row],[Nombre]] -> 0:Angel Hernandez | I563: =+dHdcp[[#This Row],[Maximo]]&":"&_xlfn.XLOOKUP(dHdcp[[#This Row],[Nombre]],dJugador[Nombre],dJugador[Mote],"",0) -> 0:Angel | J563: =+IF(dHdcp[[#This Row],[Maximo]]=0,"",_xlfn.RANK.EQ(dHdcp[[#This Row],[Handicap]],dHdcp[Handicap],1)) | K563: =IFERROR(+_xlfn.RANK.EQ(dHdcp[[#This Row],[Ranking]],dHdcp[Ranking],1),"") | M563: =+dHdcp[[#This Row],[Fecha]]&":"&dHdcp[[#This Row],[Nombre]] -> 43992:Angel Hernandez | N563: =+COUNTIF(dHdcp[Columna1],dHdcp[[#This Row],[Columna1]]) -> 2
A564: 43992 | B564: David Sequera | C564: 11 | D564: =+VLOOKUP(dHdcp[[#This Row],[Handicap]],'Categoría Hdcap'!$B$2:$E$7,4) -> 2 | E564: Fed | F564: 50fa04ad-ad99-45a1-9aa9-b55a48deb6fa | G564: =+IF(dHdcp[[#This Row],[Fecha]]=MAX(dHdcp[Fecha]),1,0) -> 0 | H564: =+dHdcp[[#This Row],[Maximo]]&":"&dHdcp[[#This Row],[Nombre]] -> 0:David Sequera | I564: =+dHdcp[[#This Row],[Maximo]]&":"&_xlfn.XLOOKUP(dHdcp[[#This Row],[Nombre]],dJugador[Nombre],dJugador[Mote],"",0) -> 0:David | J564: =+IF(dHdcp[[#This Row],[Maximo]]=0,"",_xlfn.RANK.EQ(dHdcp[[#This Row],[Handicap]],dHdcp[Handicap],1)) | K564: =IFERROR(+_xlfn.RANK.EQ(dHdcp[[#This Row],[Ranking]],dHdcp[Ranking],1),"") | M564: =+dHdcp[[#This Row],[Fecha]]&":"&dHdcp[[#This Row],[Nombre]] -> 43992:David Sequera | N564: =+COUNTIF(dHdcp[Columna1],dHdcp[[#This Row],[Columna1]]) -> 2
A565: 43992 | B565: David Sequera | C565: 10.5 | D565: 2 | E565: Cuart | F565: d91de15e-bcab-47dd-aad0-0ef2ca8c7fb9 | G565: =+IF(dHdcp[[#This Row],[Fecha]]=MAX(dHdcp[Fecha]),1,0) -> 0 | H565: =+dHdcp[[#This Row],[Maximo]]&":"&dHdcp[[#This Row],[Nombre]] -> 0:David Sequera | I565: =+dHdcp[[#This Row],[Maximo]]&":"&_xlfn.XLOOKUP(dHdcp[[#This Row],[Nombre]],dJugador[Nombre],dJugador[Mote],"",0) -> 0:David | J565: =+IF(dHdcp[[#This Row],[Maximo]]=0,"",_xlfn.RANK.EQ(dHdcp[[#This Row],[Handicap]],dHdcp[Handicap],1)) | K565: =IFERROR(+_xlfn.RANK.EQ(dHdcp[[#This Row],[Ranking]],dHdcp[Ranking],1),"") | M565: =+dHdcp[[#This Row],[Fecha]]&":"&dHdcp[[#This Row],[Nombre]] -> 43992:David Sequera | N565: =+COUNTIF(dHdcp[Columna1],dHdcp[[#This Row],[Columna1]]) -> 2
A566: 43992 | B566: Francisco Alvarez | C566: 16.2 | D566: =+VLOOKUP(dHdcp[[#This Row],[Handicap]],'Categoría Hdcap'!$B$2:$E$7,4) -> 3 | E566: Fed | F566: 15b60c81-4a84-4a72-be2a-57daeeffbf96 | G566: =+IF(dHdcp[[#This Row],[Fecha]]=MAX(dHdcp[Fecha]),1,0) -> 0 | H566: =+dHdcp[[#This Row],[Maximo]]&":"&dHdcp[[#This Row],[Nombre]] -> 0:Francisco Alvarez | I566: =+dHdcp[[#This Row],[Maximo]]&":"&_xlfn.XLOOKUP(dHdcp[[#This Row],[Nombre]],dJugador[Nombre],dJugador[Mote],"",0) -> 0:Paco | J566: =+IF(dHdcp[[#This Row],[Maximo]]=0,"",_xlfn.RANK.EQ(dHdcp[[#This Row],[Handicap]],dHdcp[Handicap],1)) | K566: =IFERROR(+_xlfn.RANK.EQ(dHdcp[[#This Row],[Ranking]],dHdcp[Ranking],1),"") | M566: =+dHdcp[[#This Row],[Fecha]]&":"&dHdcp[[#This Row],[Nombre]] -> 43992:Francisco Alvarez | N566: =+COUNTIF(dHdcp[Columna1],dHdcp[[#This Row],[Columna1]]) -> 2
A567: 43992 | B567: Francisco Alvarez | C567: 14 | D567: 3 | E567: Cuart | F567: 8c5e269f-14f6-459b-a8e2-cbab16737888 | G567: =+IF(dHdcp[[#This Row],[Fecha]]=MAX(dHdcp[Fecha]),1,0) -> 0 | H567: =+dHdcp[[#This Row],[Maximo]]&":"&dHdcp[[#This Row],[Nombre]] -> 0:Francisco Alvarez | I567: =+dHdcp[[#This Row],[Maximo]]&":"&_xlfn.XLOOKUP(dHdcp[[#This Row],[Nombre]],dJugador[Nombre],dJugador[Mote],"",0) -> 0:Paco | J567: =+IF(dHdcp[[#This Row],[Maximo]]=0,"",_xlfn.RANK.EQ(dHdcp[[#This Row],[Handicap]],dHdcp[Handicap],1)) | K567: =IFERROR(+_xlfn.RANK.EQ(dHdcp[[#This Row],[Ranking]],dHdcp[Ranking],1),"") | M567: =+dHdcp[[#This Row],[Fecha]]&":"&dHdcp[[#This Row],[Nombre]] -> 43992:Francisco Alvarez | N567: =+COUNTIF(dHdcp[Columna1],dHdcp[[#This Row],[Columna1]]) -> 2
A568: 43992 | B568: Francisco Hidalgo | C568: 15.3 | D568: =+VLOOKUP(dHdcp[[#This Row],[Handicap]],'Categoría Hdcap'!$B$2:$E$7,4) -> 3 | E568: Fed | F568: db289010-3877-4027-9584-5076fc9a38db | G568: =+IF(dHdcp[[#This Row],[Fecha]]=MAX(dHdcp[Fecha]),1,0) -> 0 | H568: =+dHdcp[[#This Row],[Maximo]]&":"&dHdcp[[#This Row],[Nombre]] -> 0:Francisco Hidalgo | I568: =+dHdcp[[#This Row],[Maximo]]&":"&_xlfn.XLOOKUP(dHdcp[[#This Row],[Nombre]],dJugador[Nombre],dJugador[Mote],"",0) -> 0:Fran | J568: =+IF(dHdcp[[#This Row],[Maximo]]=0,"",_xlfn.RANK.EQ(dHdcp[[#This Row],[Handicap]],dHdcp[Handicap],1)) | K568: =IFERROR(+_xlfn.RANK.EQ(dHdcp[[#This Row],[Ranking]],dHdcp[Ranking],1),"") | M568: =+dHdcp[[#This Row],[Fecha]]&":"&dHdcp[[#This Row],[Nombre]] -> 43992:Francisco Hidalgo | N568: =+COUNTIF(dHdcp[Columna1],dHdcp[[#This Row],[Columna1]]) -> 2
A569: 43992 | B569: Francisco Hidalgo | C569: 13.6 | D569: 3 | E569: Cuart | F569: 2778a1fa-006b-4aa8-afc2-7da35eee7fb5 | G569: =+IF(dHdcp[[#This Row],[Fecha]]=MAX(dHdcp[Fecha]),1,0) -> 0 | H569: =+dHdcp[[#This Row],[Maximo]]&":"&dHdcp[[#This Row],[Nombre]] -> 0:Francisco Hidalgo | I569: =+dHdcp[[#This Row],[Maximo]]&":"&_xlfn.XLOOKUP(dHdcp[[#This Row],[Nombre]],dJugador[Nombre],dJugador[Mote],"",0) -> 0:Fran | J569: =+IF(dHdcp[[#This Row],[Maximo]]=0,"",_xlfn.RANK.EQ(dHdcp[[#This Row],[Handicap]],dHdcp[Handicap],1)) | K569: =IFERROR(+_xlfn.RANK.EQ(dHdcp[[#This Row],[Ranking]],dHdcp[Ranking],1),"") | M569: =+dHdcp[[#This Row],[Fecha]]&":"&dHdcp[[#This Row],[Nombre]] -> 43992:Francisco Hidalgo | N569: =+COUNTIF(dHdcp[Columna1],dHdcp[[#This Row],[Columna1]]) -> 2
A570: 43992 | B570: GLEZ JUAN JOSÉ | C570: 18.2 | D570: =+VLOOKUP(dHdcp[[#This Row],[Handicap]],'Categoría Hdcap'!$B$2:$E$7,4) -> 3 | E570: Fed | F570: e6ed5722-fa50-4ebb-8eb8-0cfadd77ae96 | G570: =+IF(dHdcp[[#This Row],[Fecha]]=MAX(dHdcp[Fecha]),1,0) -> 0 | H570: =+dHdcp[[#This Row],[Maximo]]&":"&dHdcp[[#This Row],[Nombre]] -> 0:GLEZ JUAN JOSÉ | I570: =+dHdcp[[#This Row],[Maximo]]&":"&_xlfn.XLOOKUP(dHdcp[[#This Row],[Nombre]],dJugador[Nombre],dJugador[Mote],"",0) -> 0:Juanjo | J570: =+IF(dHdcp[[#This Row],[Maximo]]=0,"",_xlfn.RANK.EQ(dHdcp[[#This Row],[Handicap]],dHdcp[Handicap],1)) | K570: =IFERROR(+_xlfn.RANK.EQ(dHdcp[[#This Row],[Ranking]],dHdcp[Ranking],1),"") | M570: =+dHdcp[[#This Row],[Fecha]]&":"&dHdcp[[#This Row],[Nombre]] -> 43992:GLEZ JUAN JOSÉ | N570: =+COUNTIF(dHdcp[Columna1],dHdcp[[#This Row],[Columna1]]) -> 2
A571: 43992 | B571: GLEZ JUAN JOSÉ | C571: 17.4 | D571: 3 | E571: Cuart | F571: 24efd80d-5fbe-4613-8380-ec0316eed709 | G571: =+IF(dHdcp[[#This Row],[Fecha]]=MAX(dHdcp[Fecha]),1,0) -> 0 | H571: =+dHdcp[[#This Row],[Maximo]]&":"&dHdcp[[#This Row],[Nombre]] -> 0:GLEZ JUAN JOSÉ | I571: =+dHdcp[[#This Row],[Maximo]]&":"&_xlfn.XLOOKUP(dHdcp[[#This Row],[Nombre]],dJugador[Nombre],dJugador[Mote],"",0) -> 0:Juanjo | J571: =+IF(dHdcp[[#This Row],[Maximo]]=0,"",_xlfn.RANK.EQ(dHdcp[[#This Row],[Handicap]],dHdcp[Handicap],1)) | K571: =IFERROR(+_xlfn.RANK.EQ(dHdcp[[#This Row],[Ranking]],dHdcp[Ranking],1),"") | M571: =+dHdcp[[#This Row],[Fecha]]&":"&dHdcp[[#This Row],[Nombre]] -> 43992:GLEZ JUAN JOSÉ | N571: =+COUNTIF(dHdcp[Columna1],dHdcp[[#This Row],[Columna1]]) -> 2
A572: 43992 | B572: Ignacio Cadarso | C572: 6.1 | D572: =+VLOOKUP(dHdcp[[#This Row],[Handicap]],'Categoría Hdcap'!$B$2:$E$7,4) -> 2 | E572: Fed | F572: 4a4d86ee-eecc-4d90-81d9-d838a6640c85 | G572: =+IF(dHdcp[[#This Row],[Fecha]]=MAX(dHdcp[Fecha]),1,0) -> 0 | H572: =+dHdcp[[#This Row],[Maximo]]&":"&dHdcp[[#This Row],[Nombre]] -> 0:Ignacio Cadarso | I572: =+dHdcp[[#This Row],[Maximo]]&":"&_xlfn.XLOOKUP(dHdcp[[#This Row],[Nombre]],dJugador[Nombre],dJugador[Mote],"",0) -> 0:Ignacio | J572: =+IF(dHdcp[[#This Row],[Maximo]]=0,"",_xlfn.RANK.EQ(dHdcp[[#This Row],[Handicap]],dHdcp[Handicap],1)) | K572: =IFERROR(+_xlfn.RANK.EQ(dHdcp[[#This Row],[Ranking]],dHdcp[Ranking],1),"") | M572: =+dHdcp[[#This Row],[Fecha]]&":"&dHdcp[[#This Row],[Nombre]] -> 43992:Ignacio Cadarso | N572: =+COUNTIF(dHdcp[Columna1],dHdcp[[#This Row],[Columna1]]) -> 2
A573: 43992 | B573: Ignacio Cadarso | C573: 4.9 | D573: 2 | E573: Cuart | F573: 6328a1fb-e07a-4de3-be67-d9eb7e7fbd9b | G573: =+IF(dHdcp[[#This Row],[Fecha]]=MAX(dHdcp[Fecha]),1,0) -> 0 | H573: =+dHdcp[[#This Row],[Maximo]]&":"&dHdcp[[#This Row],[Nombre]] -> 0:Ignacio Cadarso | I573: =+dHdcp[[#This Row],[Maximo]]&":"&_xlfn.XLOOKUP(dHdcp[[#This Row],[Nombre]],dJugador[Nombre],dJugador[Mote],"",0) -> 0:Ignacio | J573: =+IF(dHdcp[[#This Row],[Maximo]]=0,"",_xlfn.RANK.EQ(dHdcp[[#This Row],[Handicap]],dHdcp[Handicap],1)) | K573: =IFERROR(+_xlfn.RANK.EQ(dHdcp[[#This Row],[Ranking]],dHdcp[Ranking],1),"") | M573: =+dHdcp[[#This Row],[Fecha]]&":"&dHdcp[[#This Row],[Nombre]] -> 43992:Ignacio Cadarso | N573: =+COUNTIF(dHdcp[Columna1],dHdcp[[#This Row],[Columna1]]) -> 2
A574: 43992 | B574: J. Enrique Gonzalez | C574: 20.1 | D574: =+VLOOKUP(dHdcp[[#This Row],[Handicap]],'Categoría Hdcap'!$B$2:$E$7,4) -> 4 | E574: Fed | F574: ad84fb0e-894b-4e1b-8fdd-a3be1e898e2b | G574: =+IF(dHdcp[[#This Row],[Fecha]]=MAX(dHdcp[Fecha]),1,0) -> 0 | H574: =+dHdcp[[#This Row],[Maximo]]&":"&dHdcp[[#This Row],[Nombre]] -> 0:J. Enrique Gonzalez | I574: =+dHdcp[[#This Row],[Maximo]]&":"&_xlfn.XLOOKUP(dHdcp[[#This Row],[Nombre]],dJugador[Nombre],dJugador[Mote],"",0) -> 0:Kike | J574: =+IF(dHdcp[[#This Row],[Maximo]]=0,"",_xlfn.RANK.EQ(dHdcp[[#This Row],[Handicap]],dHdcp[Handicap],1)) | K574: =IFERROR(+_xlfn.RANK.EQ(dHdcp[[#This Row],[Ranking]],dHdcp[Ranking],1),"") | M574: =+dHdcp[[#This Row],[Fecha]]&":"&dHdcp[[#This Row],[Nombre]] -> 43992:J. Enrique Gonzalez | N574: =+COUNTIF(dHdcp[Columna1],dHdcp[[#This Row],[Columna1]]) -> 2
A575: 43992 | B575: J. Enrique Gonzalez | C575: 17.9 | D575: 3 | E575: Cuart | F575: fc1fca13-38a1-4235-aae0-f343e9025f9b | G575: =+IF(dHdcp[[#This Row],[Fecha]]=MAX(dHdcp[Fecha]),1,0) -> 0 | H575: =+dHdcp[[#This Row],[Maximo]]&":"&dHdcp[[#This Row],[Nombre]] -> 0:J. Enrique Gonzalez | I575: =+dHdcp[[#This Row],[Maximo]]&":"&_xlfn.XLOOKUP(dHdcp[[#This Row],[Nombre]],dJugador[Nombre],dJugador[Mote],"",0) -> 0:Kike | J575: =+IF(dHdcp[[#This Row],[Maximo]]=0,"",_xlfn.RANK.EQ(dHdcp[[#This Row],[Handicap]],dHdcp[Handicap],1)) | K575: =IFERROR(+_xlfn.RANK.EQ(dHdcp[[#This Row],[Ranking]],dHdcp[Ranking],1),"") | M575: =+dHdcp[[#This Row],[Fecha]]&":"&dHdcp[[#This Row],[Nombre]] -> 43992:J. Enrique Gonzalez | N575: =+COUNTIF(dHdcp[Columna1],dHdcp[[#This Row],[Columna1]]) -> 2
A576: 43992 | B576: Javier Cervera | C576: 15.4 | D576: =+VLOOKUP(dHdcp[[#This Row],[Handicap]],'Categoría Hdcap'!$B$2:$E$7,4) -> 3 | E576: Fed | F576: e6d9b9b6-2422-4204-bd95-fa13743c48f5 | G576: =+IF(dHdcp[[#This Row],[Fecha]]=MAX(dHdcp[Fecha]),1,0) -> 0 | H576: =+dHdcp[[#This Row],[Maximo]]&":"&dHdcp[[#This Row],[Nombre]] -> 0:Javier Cervera | I576: =+dHdcp[[#This Row],[Maximo]]&":"&_xlfn.XLOOKUP(dHdcp[[#This Row],[Nombre]],dJugador[Nombre],dJugador[Mote],"",0) -> 0:Virus | J576: =+IF(dHdcp[[#This Row],[Maximo]]=0,"",_xlfn.RANK.EQ(dHdcp[[#This Row],[Handicap]],dHdcp[Handicap],1)) | K576: =IFERROR(+_xlfn.RANK.EQ(dHdcp[[#This Row],[Ranking]],dHdcp[Ranking],1),"") | M576: =+dHdcp[[#This Row],[Fecha]]&":"&dHdcp[[#This Row],[Nombre]] -> 43992:Javier Cervera | N576: =+COUNTIF(dHdcp[Columna1],dHdcp[[#This Row],[Columna1]]) -> 2
A577: 43992 | B577: Javier Cervera | C577: 13.8 | D577: 3 | E577: Cuart | F577: adc7da63-12bd-400e-a41d-299f275b0241 | G577: =+IF(dHdcp[[#This Row],[Fecha]]=MAX(dHdcp[Fecha]),1,0) -> 0 | H577: =+dHdcp[[#This Row],[Maximo]]&":"&dHdcp[[#This Row],[Nombre]] -> 0:Javier Cervera | I577: =+dHdcp[[#This Row],[Maximo]]&":"&_xlfn.XLOOKUP(dHdcp[[#This Row],[Nombre]],dJugador[Nombre],dJugador[Mote],"",0) -> 0:Virus | J577: =+IF(dHdcp[[#This Row],[Maximo]]=0,"",_xlfn.RANK.EQ(dHdcp[[#This Row],[Handicap]],dHdcp[Handicap],1)) | K577: =IFERROR(+_xlfn.RANK.EQ(dHdcp[[#This Row],[Ranking]],dHdcp[Ranking],1),"") | M577: =+dHdcp[[#This Row],[Fecha]]&":"&dHdcp[[#This Row],[Nombre]] -> 43992:Javier Cervera | N577: =+COUNTIF(dHdcp[Columna1],dHdcp[[#This Row],[Columna1]]) -> 2
A578: 43992 | B578: Javier Gonzalez Salvador | C578: 15.2 | D578: =+VLOOKUP(dHdcp[[#This Row],[Handicap]],'Categoría Hdcap'!$B$2:$E$7,4) -> 3 | E578: Fed | F578: 615a7f8d-61e6-497a-a665-3f08793477a1 | G578: =+IF(dHdcp[[#This Row],[Fecha]]=MAX(dHdcp[Fecha]),1,0) -> 0 | H578: =+dHdcp[[#This Row],[Maximo]]&":"&dHdcp[[#This Row],[Nombre]] -> 0:Javier Gonzalez Salvador | I578: =+dHdcp[[#This Row],[Maximo]]&":"&_xlfn.XLOOKUP(dHdcp[[#This Row],[Nombre]],dJugador[Nombre],dJugador[Mote],"",0) -> 0:Javi | J578: =+IF(dHdcp[[#This Row],[Maximo]]=0,"",_xlfn.RANK.EQ(dHdcp[[#This Row],[Handicap]],dHdcp[Handicap],1)) | K578: =IFERROR(+_xlfn.RANK.EQ(dHdcp[[#This Row],[Ranking]],dHdcp[Ranking],1),"") | M578: =+dHdcp[[#This Row],[Fecha]]&":"&dHdcp[[#This Row],[Nombre]] -> 43992:Javier Gonzalez Salvador | N578: =+COUNTIF(dHdcp[Columna1],dHdcp[[#This Row],[Columna1]]) -> 2
A579: 43992 | B579: Javier Gonzalez Salvador | C579: 10.9 | D579: 2 | E579: Cuart | F579: 09def411-86b1-4f52-8b14-a2fb904919b4 | G579: =+IF(dHdcp[[#This Row],[Fecha]]=MAX(dHdcp[Fecha]),1,0) -> 0 | H579: =+dHdcp[[#This Row],[Maximo]]&":"&dHdcp[[#This Row],[Nombre]] -> 0:Javier Gonzalez Salvador | I579: =+dHdcp[[#This Row],[Maximo]]&":"&_xlfn.XLOOKUP(dHdcp[[#This Row],[Nombre]],dJugador[Nombre],dJugador[Mote],"",0) -> 0:Javi | J579: =+IF(dHdcp[[#This Row],[Maximo]]=0,"",_xlfn.RANK.EQ(dHdcp[[#This Row],[Handicap]],dHdcp[Handicap],1)) | K579: =IFERROR(+_xlfn.RANK.EQ(dHdcp[[#This Row],[Ranking]],dHdcp[Ranking],1),"") | M579: =+dHdcp[[#This Row],[Fecha]]&":"&dHdcp[[#This Row],[Nombre]] -> 43992:Javier Gonzalez Salvador | N579: =+COUNTIF(dHdcp[Columna1],dHdcp[[#This Row],[Columna1]]) -> 2
A580: 43992 | B580: Jesus Touceda | C580: 22.6 | D580: =+VLOOKUP(dHdcp[[#This Row],[Handicap]],'Categoría Hdcap'!$B$2:$E$7,4) -> 4 | E580: Fed | F580: 8b0ca66b-55c1-4861-95ba-62cb38e43938 | G580: =+IF(dHdcp[[#This Row],[Fecha]]=MAX(dHdcp[Fecha]),1,0) -> 0 | H580: =+dHdcp[[#This Row],[Maximo]]&":"&dHdcp[[#This Row],[Nombre]] -> 0:Jesus Touceda | I580: =+dHdcp[[#This Row],[Maximo]]&":"&_xlfn.XLOOKUP(dHdcp[[#This Row],[Nombre]],dJugador[Nombre],dJugador[Mote],"",0) -> 0:Jesús | J580: =+IF(dHdcp[[#This Row],[Maximo]]=0,"",_xlfn.RANK.EQ(dHdcp[[#This Row],[Handicap]],dHdcp[Handicap],1)) | K580: =IFERROR(+_xlfn.RANK.EQ(dHdcp[[#This Row],[Ranking]],dHdcp[Ranking],1),"") | M580: =+dHdcp[[#This Row],[Fecha]]&":"&dHdcp[[#This Row],[Nombre]] -> 43992:Jesus Touceda | N580: =+COUNTIF(dHdcp[Columna1],dHdcp[[#This Row],[Columna1]]) -> 2
